Workbook

Sheet 250618_coverm_sum_mec_DNA_95_co
A1: Sample | B1: Genome | C1: Mean | D1: Trimmed Mean | E1: Covered Bases | F1: Variance | G1: Length | H1: Count | I1: Reads_per_base | J1: RPKM_DNA | K1: TPM | L1: SampleID | M1: Total_DNA_reads | N1: NEC_onset2 | O1: NEC_status | P1: DOL | Q1: Days_before_NEC_onset | R1: Patient | S1: norm_DNA_tpmean | T1: Phage | U1: 9ImpVir
A2: 116_01267_53_116-01_1 | B2: 116_01267_53 | C2: 0 | D2: 0 | E2: 0 | F2: 0 | G2: 711 | H2: 0 | I2: 0 | J2: 0 | K2: 0 | L2: 116-01_1 | M2: 6635730 | N2: Late | O2: case | P2: 23 | Q2: 25 | R2: 116-01 | S2: =D2/M2*1000000000 -> 0 | T2: 116_01267 | U2: =VLOOKUP(T2,Sheet2!$A$2:$B$622,2,FALSE) -> Yes
A3: 116_01267_53_116-01_2 | B3: 116_01267_53 | C3: 0 | D3: 0 | E3: 0 | F3: 0 | G3: 711 | H3: 0 | I3: 0 | J3: 0 | K3: 0 | L3: 116-01_2 | M3: 7324292 | N3: Late | O3: case | P3: 27 | Q3: 21 | R3: 116-01 | S3: =D3/M3*1000000000 -> 0 | T3: 116_01267 | U3: =VLOOKUP(T3,Sheet2!$A$2:$B$622,2,FALSE) -> Yes
A4: 116_01267_53_116-01_3 | B4: 116_01267_53 | C4: 0 | D4: 0 | E4: 0 | F4: 0 | G4: 711 | H4: 0 | I4: 0 | J4: 0 | K4: 0 | L4: 116-01_3 | M4: 11047380 | N4: Late | O4: case | P4: 28 | Q4: 20 | R4: 116-01 | S4: =D4/M4*1000000000 -> 0 | T4: 116_01267 | U4: =VLOOKUP(T4,Sheet2!$A$2:$B$622,2,FALSE) -> Yes
A5: 116_01267_53_116-01_4 | B5: 116_01267_53 | C5: 0 | D5: 0 | E5: 0 | F5: 0 | G5: 711 | H5: 0 | I5: 0 | J5: 0 | K5: 0 | L5: 116-01_4 | M5: 6314202 | N5: Late | O5: case | P5: 30 | Q5: 18 | R5: 116-01 | S5: =D5/M5*1000000000 -> 0 | T5: 116_01267 | U5: =VLOOKUP(T5,Sheet2!$A$2:$B$622,2,FALSE) -> Yes
A6: 116_01267_53_116-01_5 | B6: 116_01267_53 | C6: 0 | D6: 0 | E6: 0 | F6: 0 | G6: 711 | H6: 0 | I6: 0 | J6: 0 | K6: 0 | L6: 116-01_5 | M6: 9132466 | N6: Late | O6: case | P6: 32 | Q6: 16 | R6: 116-01 | S6: =D6/M6*1000000000 -> 0 | T6: 116_01267 | U6: =VLOOKUP(T6,Sheet2!$A$2:$B$622,2,FALSE) -> Yes
A7: 116_01267_53_116-01_6 | B7: 116_01267_53 | C7: 0 | D7: 0 | E7: 0 | F7: 0 | G7: 711 | H7: 0 | I7: 0 | J7: 0 | K7: 0 | L7: 116-01_6 | M7: 9084570 | N7: Late | O7: case | P7: 34 | Q7: 14 | R7: 116-01 | S7: =D7/M7*1000000000 -> 0 | T7: 116_01267 | U7: =VLOOKUP(T7,Sheet2!$A$2:$B$622,2,FALSE) -> Yes
A8: 116_01267_53_116-01_7 | B8: 116_01267_53 | C8: 9.431373 | D8: 9.281188 | E8: 701 | F8: 21.892157 | G8: 711 | H8: 43 | I8: 0.0604782 | J8: 1406469.8 | K8: 1000000 | L8: 116-01_7 | M8: 11748018 | N8: Late | O8: case | P8: 35 | Q8: 13 | R8: 116-01 | S8: =D8/M8*1000000000 -> 790.0216 | T8: 116_01267 | U8: =VLOOKUP(T8,Sheet2!$A$2:$B$622,2,FALSE) -> Yes
A9: 116_01267_53_116-01_8 | B9: 116_01267_53 | C9: 192.42245 | D9: 194.01782 | E9: 711 | F9: 768.64465 | G9: 711 | H9: 904 | I9: 1.2714486 | J9: 1406469.6 | K9: 1000000 | L9: 116-01_8 | M9: 16649350 | N9: Late | O9: case | P9: 38 | Q9: 10 | R9: 116-01 | S9: =D9/M9*1000000000 -> 11653.177 | T9: 116_01267 | U9: =VLOOKUP(T9,Sheet2!$A$2:$B$622,2,FALSE) -> Yes
A10: 116_01267_53_116-01_9 | B10: 116_01267_53 | C10: 19.43672 | D10: 19.639605 | E10: 697 | F10: 11.900007 | G10: 711 | H10: 94 | I10: 0.13220815 | J10: 1406469.8 | K10: 1000000 | L10: 116-01_9 | M10: 11562392 | N10: Late | O10: case | P10: 39 | Q10: 9 | R10: 116-01 | S10: =D10/M10*1000000000 -> 1698.5763 | T10: 116_01267 | U10: =VLOOKUP(T10,Sheet2!$A$2:$B$622,2,FALSE) -> Yes
A11: 116_01267_53_116-01_10 | B11: 116_01267_53 | C11: 20.253119 | D11: 20.20396 | E11: 691 | F11: 17.621532 | G11: 711 | H11: 92 | I11: 0.12939522 | J11: 1406469.9 | K11: 1000000 | L11: 116-01_10 | M11: 10512310 | N11: Late | O11: case | P11: 40 | Q11: 8 | R11: 116-01 | S11: =D11/M11*1000000000 -> 1921.9334 | T11: 116_01267 | U11: =VLOOKUP(T11,Sheet2!$A$2:$B$622,2,FALSE) -> Yes
A12: 116_01267_53_116-01_11 | B12: 116_01267_53 | C12: 39.40998 | D12: 39.681187 | E12: 701 | F12: 128.9745 | G12: 711 | H12: 182 | I12: 0.25597748 | J12: 1406469.8 | K12: 1000000 | L12: 116-01_11 | M12: 9681008 | N12: Late | O12: case | P12: 41 | Q12: 7 | R12: 116-01 | S12: =D12/M12*1000000000 -> 4098.8694 | T12: 116_01267 | U12: =VLOOKUP(T12,Sheet2!$A$2:$B$622,2,FALSE) -> Yes
A13: 116_01267_53_116-01_12 | B13: 116_01267_53 | C13: 18.900179 | D13: 19.021782 | E13: 698 | F13: 9.315018 | G13: 711 | H13: 90 | I13: 0.12658228 | J13: 1406469.8 | K13: 1000000 | L13: 116-01_12 | M13: 12801140 | N13: Late | O13: case | P13: 44 | Q13: 4 | R13: 116-01 | S13: =D13/M13*1000000000 -> 1485.9444 | T13: 116_01267 | U13: =VLOOKUP(T13,Sheet2!$A$2:$B$622,2,FALSE) -> Yes
... A131: 352_0185_3_352-01_20 | B131: 352_0185_3 | C131: 1.5401235 | D131: 1.5119863 | E131: 392 | F131: 1.8840135 | G131: 798 | H131: 8 | I131: 0.010025063 | J131: 1253132.9 | K131: 1000000 | L131: 352-01_20 | M131: 14601176 | N131: Late | O131: control | P131: 55 | Q131: 1 | R131: 352-01 | S131: =D131/M131*1000000000 -> 103.55236 | T131: 352_0185 | U131: =VLOOKUP(T131,Sheet2!$A$2:$B$622,2,FALSE) -> Yes
A132: S101C267_01765_vs01_1_267-01_5 | B132: S101C267_01765_vs01_1 | C132: 0 | D132: 0 | E132: 0 | F132: 0 | G132: 711 | H132: 0 | I132: 0 | J132: 0 | K132: 0 | L132: 267-01_5 | M132: 10754064 | N132: Late | O132: control | P132: 13 | Q132: 38 | R132: 267-01 | S132: =D132/M132*1000000000 -> 0 | T132: S101C267_01765_vs01 | U132: No
A133: S101C267_01765_vs01_1_267-01_6 | B133: S101C267_01765_vs01_1 | C133: 0 | D133: 0 | E133: 0 | F133: 0 | G133: 711 | H133: 0 | I133: 0 | J133: 0 | K133: 0 | L133: 267-01_6 | M133: 6814474 | N133: Late | O133: control | P133: 15 | Q133: 36 | R133: 267-01 | S133: =D133/M133*1000000000 -> 0 | T133: S101C267_01765_vs01 | U133: No
A134: S101C267_01765_vs01_1_267_01_7 | B134: S101C267_01765_vs01_1 | C134: 0 | D134: 0 | E134: 0 | F134: 0 | G134: 711 | H134: 0 | I134: 0 | J134: 0 | K134: 0 | L134: 267_01_7 | M134: 5457390 | N134: Late | O134: control | P134: 16 | Q134: 35 | R134: 267-01 | S134: =D134/M134*1000000000 -> 0 | T134: S101C267_01765_vs01 | U134: No
A135: S101C267_01765_vs01_1_267-01_8 | B135: S101C267_01765_vs01_1 | C135: 0 | D135: 0 | E135: 0 | F135: 0 | G135: 711 | H135: 0 | I135: 0 | J135: 0 | K135: 0 | L135: 267-01_8 | M135: 11326012 | N135: Late | O135: control | P135: 17 | Q135: 34 | R135: 267-01 | S135: =D135/M135*1000000000 -> 0 | T135: S101C267_01765_vs01 | U135: No
A136: S101C267_01765_vs01_1_267_01_9 | B136: S101C267_01765_vs01_1 | C136: 0 | D136: 0 | E136: 0 | F136: 0 | G136: 711 | H136: 0 | I136: 0 | J136: 0 | K136: 0 | L136: 267_01_9 | M136: 5739310 | N136: Late | O136: control | P136: 21 | Q136: 30 | R136: 267-01 | S136: =D136/M136*1000000000 -> 0 | T136: S101C267_01765_vs01 | U136: No
A137: S101C267_01765_vs01_1_267-01_10 | B137: S101C267_01765_vs01_1 | C137: 0 | D137: 0 | E137: 0 | F137: 0 | G137: 711 | H137: 0 | I137: 0 | J137: 0 | K137: 0 | L137: 267-01_10 | M137: 5439410 | N137: Late | O137: control | P137: 24 | Q137: 27 | R137: 267-01 | S137: =D137/M137*1000000000 -> 0 | T137: S101C267_01765_vs01 | U137: No
A138: S101C267_01765_vs01_1_267_01_11 | B138: S101C267_01765_vs01_1 | C138: 0 | D138: 0 | E138: 0 | F138: 0 | G138: 711 | H138: 0 | I138: 0 | J138: 0 | K138: 0 | L138: 267_01_11 | M138: 5915800 | N138: Late | O138: control | P138: 25 | Q138: 26 | R138: 267-01 | S138: =D138/M138*1000000000 -> 0 | T138: S101C267_01765_vs01 | U138: No
A139: S101C267_01765_vs01_1_267-01_13 | B139: S101C267_01765_vs01_1 | C139: 0 | D139: 0 | E139: 0 | F139: 0 | G139: 711 | H139: 0 | I139: 0 | J139: 0 | K139: 0 | L139: 267-01_13 | M139: 5058062 | N139: Late | O139: control | P139: 28 | Q139: 23 | R139: 267-01 | S139: =D139/M139*1000000000 -> 0 | T139: S101C267_01765_vs01 | U139: No
A140: S101C267_01765_vs01_1_267-01_1 | B140: S101C267_01765_vs01_1 | C140: 0 | D140: 0 | E140: 0 | F140: 0 | G140: 711 | H140: 0 | I140: 0 | J140: 0 | K140: 0 | L140: 267-01_1 | M140: 9329134 | N140: Late | O140: control | P140: 29 | Q140: 22 | R140: 267-01 | S140: =D140/M140*1000000000 -> 0 | T140: S101C267_01765_vs01 | U140: No
A141: S101C267_01765_vs01_1_267-01_2 | B141: S101C267_01765_vs01_1 | C141: 0 | D141: 0 | E141: 0 | F141: 0 | G141: 711 | H141: 0 | I141: 0 | J141: 0 | K141: 0 | L141: 267-01_2 | M141: 15491080 | N141: Late | O141: control | P141: 30 | Q141: 21 | R141: 267-01 | S141: =D141/M141*1000000000 -> 0 | T141: S101C267_01765_vs01 | U141: No
A142: S101C267_01765_vs01_1_267-01_14 | B142: S101C267_01765_vs01_1 | C142: 0 | D142: 0 | E142: 0 | F142: 0 | G142: 711 | H142: 0 | I142: 0 | J142: 0 | K142: 0 | L142: 267-01_14 | M142: 6180372 | N142: Late | O142: control | P142: 31 | Q142: 20 | R142: 267-01 | S142: =D142/M142*1000000000 -> 0 | T142: S101C267_01765_vs01 | U142: No
A143: S101C267_01765_vs01_1_267_01_15 | B143: S101C267_01765_vs01_1 | C143: 0 | D143: 0 | E143: 0 | F143: 0 | G143: 711 | H143: 0 | I143: 0 | J143: 0 | K143: 0 | L143: 267_01_15 | M143: 5494180 | N143: Late | O143: control | P143: 32 | Q143: 19 | R143: 267-01 | S143: =D143/M143*1000000000 -> 0 | T143: S101C267_01765_vs01 | U143: No
... A266: S102C271_013411_vs01_7_271-01_24 | B266: S102C271_013411_vs01_7 | C266: 12.735816 | D266: 12.698819 | E266: 709 | F266: 28.684967 | G266: 714 | H266: 67 | I266: 0.09383754 | J266: 1400560.3 | K266: 1000000 | L266: 271-01_24 | M266: 11460184 | N266: Late | O266: control | P266: 46 | Q266: 2 | R266: 271-01 | S266: =D266/M266*1000000000 -> 1108.0816 | T266: S102C271_013411_vs01 | U266: No
A267: S105C280_017_vs01_32_280-01_5 | B267: S105C280_017_vs01_32 | C267: 83.95544 | D267: 85.518814 | E267: 698 | F267: 212.7605 | G267: 711 | H267: 398 | I267: 0.55977494 | J267: 1406469.8 | K267: 1000000 | L267: 280-01_5 | M267: 10952454 | N267: Early | O267: case | P267: 9 | Q267: 4 | R267: 280-01 | S267: =D267/M267*1000000000 -> 7808.1875 | T267: S105C280_017_vs01 | U267: =VLOOKUP(T267,Sheet2!$A$2:$B$622,2,FALSE) -> Yes
A268: S105C280_017_vs01_32_280-01_6 | B268: S105C280_017_vs01_32 | C268: 70.68984 | D268: 71.53664 | E268: 711 | F268: 228.45012 | G268: 711 | H268: 328 | I268: 0.46132207 | J268: 1406469.9 | K268: 1000000 | L268: 280-01_6 | M268: 4597910 | N268: Early | O268: case | P268: 10 | Q268: 3 | R268: 280-01 | S268: =D268/M268*1000000000 -> 15558.512 | T268: S105C280_017_vs01 | U268: =VLOOKUP(T268,Sheet2!$A$2:$B$622,2,FALSE) -> Yes
A269: S105C280_017_vs01_32_280-01_7 | B269: S105C280_017_vs01_32 | C269: 176.15686 | D269: 178.77426 | E269: 706 | F269: 491.9326 | G269: 711 | H269: 804 | I269: 1.1308017 | J269: 1406469.8 | K269: 1000000 | L269: 280-01_7 | M269: 13801284 | N269: Early | O269: case | P269: 11 | Q269: 2 | R269: 280-01 | S269: =D269/M269*1000000000 -> 12953.451 | T269: S105C280_017_vs01 | U269: =VLOOKUP(T269,Sheet2!$A$2:$B$622,2,FALSE) -> Yes
A270: S105C280_017_vs01_32_280-01_8 | B270: S105C280_017_vs01_32 | C270: 103.70232 | D270: 104.31881 | E270: 711 | F270: 389.0309 | G270: 711 | H270: 539 | I270: 0.7580872 | J270: 1406469.9 | K270: 1000000 | L270: 280-01_8 | M270: 5748320 | N270: Early | O270: case | P270: 12 | Q270: 1 | R270: 280-01 | S270: =D270/M270*1000000000 -> 18147.704 | T270: S105C280_017_vs01 | U270: =VLOOKUP(T270,Sheet2!$A$2:$B$622,2,FALSE) -> Yes
A271: S105C280_017_vs01_32_280-01_9 | B271: S105C280_017_vs01_32 | C271: 152.25134 | D271: 152.45941 | E271: 711 | F271: 256.45993 | G271: 711 | H271: 702 | I271: 0.98734176 | J271: 1406469.8 | K271: 1000000 | L271: 280-01_9 | M271: 9397950 | N271: Early | O271: case | P271: 13 | Q271: 0 | R271: 280-01 | S271: =D271/M271*1000000000 -> 16222.624 | T271: S105C280_017_vs01 | U271: =VLOOKUP(T271,Sheet2!$A$2:$B$622,2,FALSE) -> Yes
A272: S106C282_01216_vs01_49_282-01_1 | B272: S106C282_01216_vs01_49 | C272: 0 | D272: 0 | E272: 0 | F272: 0 | G272: 711 | H272: 0 | I272: 0 | J272: 0 | K272: 0 | L272: 282-01_1 | M272: 12732898 | N272: Early | O272: control | P272: 1 | Q272: 19 | R272: 282-01 | S272: =D272/M272*1000000000 -> 0 | T272: S106C282_01216_vs01 | U272: =VLOOKUP(T272,Sheet2!$A$2:$B$622,2,FALSE) -> Yes
A273: S106C282_01216_vs01_49_282-01_2 | B273: S106C282_01216_vs01_49 | C273: 0 | D273: 0 | E273: 0 | F273: 0 | G273: 711 | H273: 0 | I273: 0 | J273: 0 | K273: 0 | L273: 282-01_2 | M273: 9063052 | N273: Early | O273: control | P273: 8 | Q273: 12 | R273: 282-01 | S273: =D273/M273*1000000000 -> 0 | T273: S106C282_01216_vs01 | U273: =VLOOKUP(T273,Sheet2!$A$2:$B$622,2,FALSE) -> Yes
A274: S106C282_01216_vs01_49_282-01_3 | B274: S106C282_01216_vs01_49 | C274: 0 | D274: 0 | E274: 0 | F274: 0 | G274: 711 | H274: 0 | I274: 0 | J274: 0 | K274: 0 | L274: 282-01_3 | M274: 11133458 | N274: Early | O274: control | P274: 9 | Q274: 11 | R274: 282-01 | S274: =D274/M274*1000000000 -> 0 | T274: S106C282_01216_vs01 | U274: =VLOOKUP(T274,Sheet2!$A$2:$B$622,2,FALSE) -> Yes
A275: S106C282_01216_vs01_49_282-01_4 | B275: S106C282_01216_vs01_49 | C275: 0 | D275: 0 | E275: 0 | F275: 0 | G275: 711 | H275: 0 | I275: 0 | J275: 0 | K275: 0 | L275: 282-01_4 | M275: 12151782 | N275: Early | O275: control | P275: 10 | Q275: 10 | R275: 282-01 | S275: =D275/M275*1000000000 -> 0 | T275: S106C282_01216_vs01 | U275: =VLOOKUP(T275,Sheet2!$A$2:$B$622,2,FALSE) -> Yes
A276: S106C282_01216_vs01_49_282-01_5 | B276: S106C282_01216_vs01_49 | C276: 0 | D276: 0 | E276: 0 | F276: 0 | G276: 711 | H276: 0 | I276: 0 | J276: 0 | K276: 0 | L276: 282-01_5 | M276: 12556454 | N276: Early | O276: control | P276: 11 | Q276: 9 | R276: 282-01 | S276: =D276/M276*1000000000 -> 0 | T276: S106C282_01216_vs01 | U276: =VLOOKUP(T276,Sheet2!$A$2:$B$622,2,FALSE) -> Yes
A277: S106C282_01216_vs01_49_282-01_6 | B277: S106C282_01216_vs01_49 | C277: 0 | D277: 0 | E277: 0 | F277: 0 | G277: 711 | H277: 0 | I277: 0 | J277: 0 | K277: 0 | L277: 282-01_6 | M277: 10236404 | N277: Early | O277: control | P277: 12 | Q277: 8 | R277: 282-01 | S277: =D277/M277*1000000000 -> 0 | T277: S106C282_01216_vs01 | U277: =VLOOKUP(T277,Sheet2!$A$2:$B$622,2,FALSE) -> Yes
A278: S106C282_01216_vs01_49_282-01_7 | B278: S106C282_01216_vs01_49 | C278: 0 | D278: 0 | E278: 0 | F278: 0 | G278: 711 | H278: 0 | I278: 0 | J278: 0 | K278: 0 | L278: 282-01_7 | M278: 11354864 | N278: Early | O278: control | P278: 14 | Q278: 6 | R278: 282-01 | S278: =D278/M278*1000000000 -> 0 | T278: S106C282_01216_vs01 | U278: =VLOOKUP(T278,Sheet2!$A$2:$B$622,2,FALSE) -> Yes
... A301: S106C282_01335_vs01_3_282-01_10 | B301: S106C282_01335_vs01_3 | C301: 14.677193 | D301: 14.455253 | E301: 704 | F301: 21.892094 | G301: 720 | H301: 74 | I301: 0.10277778 | J301: 1388888.9 | K301: 1000000 | L301: 282-01_10 | M301: 10804206 | N301: Early | O301: control | P301: 19 | Q301: 1 | R301: 282-01 | S301: =D301/M301*1000000000 -> 1337.9283 | T301: S106C282_01335_vs01 | U301: =VLOOKUP(T301,Sheet2!$A$2:$B$622,2,FALSE) -> Yes
...

Sheet Sheet1
A1: SampleID | B1: NEC_onset2 | C1: NEC_status | D1: DOL | E1: Days_before_NEC_onset | F1: Patient
A2: 1003_01_10 | B2: Late | C2: case | D2: 19 | E2: 49 | F2: 1003-01
A3: 1003_01_11 | B3: Late | C3: case | D3: 20 | E3: 48 | F3: 1003-01
A4: 1003_01_12 | B4: Late | C4: case | D4: 21 | E4: 47 | F4: 1003-01
A5: 1003_01_13 | B5: Late | C5: case | D5: 22 | E5: 46 | F5: 1003-01
A6: 1003_01_14 | B6: Late | C6: case | D6: 25 | E6: 43 | F6: 1003-01
A7: 1003_01_15 | B7: Late | C7: case | D7: 26 | E7: 42 | F7: 1003-01
A8: 1003_01_16 | B8: Late | C8: case | D8: 27 | E8: 41 | F8: 1003-01
A9: 1003_01_17 | B9: Late | C9: case | D9: 28 | E9: 40 | F9: 1003-01
A10: 1003_01_18 | B10: Late | C10: case | D10: 29 | E10: 39 | F10: 1003-01
A11: 1003_01_19 | B11: Late | C11: case | D11: 30 | E11: 38 | F11: 1003-01
A12: 1003_01_2 | B12: Late | C12: case | D12: 9 | E12: 59 | F12: 1003-01
A13: 1003_01_20 | B13: Late | C13: case | D13: 31 | E13: 37 | F13: 1003-01
... A1826: 95_01_4 | B1826: Early | C1826: case | D1826: 13 | E1826: 7 | F1826: 95-01

Sheet Sheet2
A1: Contig | B1: 9ImpVir
A2: S1C1003_01249_vs01 | B2: Yes
A3: S22C131_01414_vs01 | B3: Yes
A4: S51C2050_012192_vs01 | B4: Yes
A5: S68C2146_01267_vs01 | B5: Yes
A6: S72C2166_01630_vs01 | B6: Yes
A7: S106C282_01237_vs01 | B7: Yes
A8: S124C383_01872_vs01 | B8: Yes
A9: S128C399_01195_vs01 | B9: Yes
A10: S131C410_011685_vs01 | B10: Yes
A11: S131C410_014857_vs01 | B11: Yes
A12: S139C52_011224_vs01 | B12: Yes
... A622: S80C2199_021410_vs01 | B622: Yes
